2023-04-11 17:01:00,206 ERROR: Exception on / [GET] [in /home/keai33/Flask___Mega/venv/lib/python3.8/site-packages/flask/app.py:1744]
Traceback (most recent call last):
  File "/home/keai33/Flask___Mega/venv/lib/python3.8/site-packages/flask/app.py", line 2528, in wsgi_app
    response = self.full_dispatch_request()
  File "/home/keai33/Flask___Mega/venv/lib/python3.8/site-packages/flask/app.py", line 1825, in full_dispatch_request
    rv = self.handle_user_exception(e)
  File "/home/keai33/Flask___Mega/venv/lib/python3.8/site-packages/flask/app.py", line 1823, in full_dispatch_request
    rv = self.dispatch_request()
  File "/home/keai33/Flask___Mega/venv/lib/python3.8/site-packages/flask/app.py", line 1799, in dispatch_request
    return self.ensure_sync(self.view_functions[rule.endpoint])(**view_args)
  File "/home/keai33/Flask___Mega/venv/lib/python3.8/site-packages/flask_login/utils.py", line 290, in decorated_view
    return current_app.ensure_sync(func)(*args, **kwargs)
  File "/home/keai33/Flask___Mega/microblog/app/main/routes.py", line 49, in index
    return render_template('index.html', title=_('Home'), form=form,
  File "/home/keai33/Flask___Mega/venv/lib/python3.8/site-packages/flask/templating.py", line 147, in render_template
    return _render(app, template, context)
  File "/home/keai33/Flask___Mega/venv/lib/python3.8/site-packages/flask/templating.py", line 130, in _render
    rv = template.render(context)
  File "/home/keai33/Flask___Mega/venv/lib/python3.8/site-packages/jinja2/environment.py", line 1301, in render
    self.environment.handle_exception()
  File "/home/keai33/Flask___Mega/venv/lib/python3.8/site-packages/jinja2/environment.py", line 936, in handle_exception
    raise rewrite_traceback_stack(source=source)
  File "/home/keai33/Flask___Mega/microblog/app/templates/index.html", line 2, in top-level template code
    {% import 'bootstrap/wtf.html' as wtf %}
  File "/home/keai33/Flask___Mega/microblog/app/templates/base.html", line 1, in top-level template code
    {% extends 'bootstrap/base.html' %}
  File "/home/keai33/Flask___Mega/venv/lib/python3.8/site-packages/flask_bootstrap/templates/bootstrap/base.html", line 1, in top-level template code
    {% block doc -%}
  File "/home/keai33/Flask___Mega/venv/lib/python3.8/site-packages/flask_bootstrap/templates/bootstrap/base.html", line 4, in block 'doc'
    {%- block html %}
  File "/home/keai33/Flask___Mega/venv/lib/python3.8/site-packages/flask_bootstrap/templates/bootstrap/base.html", line 20, in block 'html'
    {% block body -%}
  File "/home/keai33/Flask___Mega/venv/lib/python3.8/site-packages/flask_bootstrap/templates/bootstrap/base.html", line 26, in block 'body'
    {% block scripts %}
  File "/home/keai33/Flask___Mega/microblog/app/templates/base.html", line 136, in block 'scripts'
    $.ajax('{{ url_for('main.notifications') }}?since=' + since).done(
  File "/home/keai33/Flask___Mega/venv/lib/python3.8/site-packages/flask/app.py", line 2034, in url_for
    return self.handle_url_build_error(error, endpoint, values)
  File "/home/keai33/Flask___Mega/venv/lib/python3.8/site-packages/flask/app.py", line 2023, in url_for
    rv = url_adapter.build(  # type: ignore[union-attr]
  File "/home/keai33/Flask___Mega/venv/lib/python3.8/site-packages/werkzeug/routing/map.py", line 917, in build
    raise BuildError(endpoint, values, method, self)
werkzeug.routing.exceptions.BuildError: Could not build url for endpoint 'main.notifications'. Did you mean 'main.unfollow' instead?
2023-04-11 19:29:17,862 INFO: Microblog startup [in /home/keai33/Flask___Mega/microblog/app/__init__.py:78]
2023-04-11 19:32:33,113 INFO: Microblog startup [in /home/keai33/Flask___Mega/microblog/app/__init__.py:78]
2023-04-11 19:32:40,046 INFO: Microblog startup [in /home/keai33/Flask___Mega/microblog/app/__init__.py:78]
2023-04-11 19:45:07,112 INFO: Microblog startup [in /home/keai33/Flask___Mega/microblog/app/__init__.py:78]
2023-04-11 19:45:32,057 ERROR: Exception on /messages [GET] [in /home/keai33/Flask___Mega/venv/lib/python3.8/site-packages/flask/app.py:1744]
Traceback (most recent call last):
  File "/home/keai33/Flask___Mega/venv/lib/python3.8/site-packages/flask/app.py", line 2528, in wsgi_app
    response = self.full_dispatch_request()
  File "/home/keai33/Flask___Mega/venv/lib/python3.8/site-packages/flask/app.py", line 1825, in full_dispatch_request
    rv = self.handle_user_exception(e)
  File "/home/keai33/Flask___Mega/venv/lib/python3.8/site-packages/flask/app.py", line 1823, in full_dispatch_request
    rv = self.dispatch_request()
  File "/home/keai33/Flask___Mega/venv/lib/python3.8/site-packages/flask/app.py", line 1799, in dispatch_request
    return self.ensure_sync(self.view_functions[rule.endpoint])(**view_args)
  File "/home/keai33/Flask___Mega/venv/lib/python3.8/site-packages/flask_login/utils.py", line 290, in decorated_view
    return current_app.ensure_sync(func)(*args, **kwargs)
  File "/home/keai33/Flask___Mega/microblog/app/main/routes.py", line 215, in messages
    current_user.add_notification('unread_message_count',0)
AttributeError: 'User' object has no attribute 'add_notification'
2023-04-11 19:46:00,959 ERROR: Exception on /send_message/Mehraz Hossain Rumman [GET] [in /home/keai33/Flask___Mega/venv/lib/python3.8/site-packages/flask/app.py:1744]
Traceback (most recent call last):
  File "/home/keai33/Flask___Mega/venv/lib/python3.8/site-packages/flask/app.py", line 2528, in wsgi_app
    response = self.full_dispatch_request()
  File "/home/keai33/Flask___Mega/venv/lib/python3.8/site-packages/flask/app.py", line 1825, in full_dispatch_request
    rv = self.handle_user_exception(e)
  File "/home/keai33/Flask___Mega/venv/lib/python3.8/site-packages/flask/app.py", line 1823, in full_dispatch_request
    rv = self.dispatch_request()
  File "/home/keai33/Flask___Mega/venv/lib/python3.8/site-packages/flask/app.py", line 1799, in dispatch_request
    return self.ensure_sync(self.view_functions[rule.endpoint])(**view_args)
  File "/home/keai33/Flask___Mega/venv/lib/python3.8/site-packages/flask_login/utils.py", line 290, in decorated_view
    return current_app.ensure_sync(func)(*args, **kwargs)
  File "/home/keai33/Flask___Mega/microblog/app/main/routes.py", line 207, in send_message
    return render_template('send_message.html', title=_('Send Message'),
  File "/home/keai33/Flask___Mega/venv/lib/python3.8/site-packages/flask/templating.py", line 146, in render_template
    template = app.jinja_env.get_or_select_template(template_name_or_list)
  File "/home/keai33/Flask___Mega/venv/lib/python3.8/site-packages/jinja2/environment.py", line 1081, in get_or_select_template
    return self.get_template(template_name_or_list, parent, globals)
  File "/home/keai33/Flask___Mega/venv/lib/python3.8/site-packages/jinja2/environment.py", line 1010, in get_template
    return self._load_template(name, globals)
  File "/home/keai33/Flask___Mega/venv/lib/python3.8/site-packages/jinja2/environment.py", line 969, in _load_template
    template = self.loader.load(self, name, self.make_globals(globals))
  File "/home/keai33/Flask___Mega/venv/lib/python3.8/site-packages/jinja2/loaders.py", line 138, in load
    code = environment.compile(source, name, filename)
  File "/home/keai33/Flask___Mega/venv/lib/python3.8/site-packages/jinja2/environment.py", line 768, in compile
    self.handle_exception(source=source_hint)
  File "/home/keai33/Flask___Mega/venv/lib/python3.8/site-packages/jinja2/environment.py", line 936, in handle_exception
    raise rewrite_traceback_stack(source=source)
  File "/home/keai33/Flask___Mega/microblog/app/templates/send_message.html", line 11, in template
    {% endblock %
jinja2.exceptions.TemplateSyntaxError: expected token 'end of statement block', got '%'
2023-04-11 19:46:36,588 ERROR: Exception on /messages [GET] [in /home/keai33/Flask___Mega/venv/lib/python3.8/site-packages/flask/app.py:1744]
Traceback (most recent call last):
  File "/home/keai33/Flask___Mega/venv/lib/python3.8/site-packages/flask/app.py", line 2528, in wsgi_app
    response = self.full_dispatch_request()
  File "/home/keai33/Flask___Mega/venv/lib/python3.8/site-packages/flask/app.py", line 1825, in full_dispatch_request
    rv = self.handle_user_exception(e)
  File "/home/keai33/Flask___Mega/venv/lib/python3.8/site-packages/flask/app.py", line 1823, in full_dispatch_request
    rv = self.dispatch_request()
  File "/home/keai33/Flask___Mega/venv/lib/python3.8/site-packages/flask/app.py", line 1799, in dispatch_request
    return self.ensure_sync(self.view_functions[rule.endpoint])(**view_args)
  File "/home/keai33/Flask___Mega/venv/lib/python3.8/site-packages/flask_login/utils.py", line 290, in decorated_view
    return current_app.ensure_sync(func)(*args, **kwargs)
  File "/home/keai33/Flask___Mega/microblog/app/main/routes.py", line 215, in messages
    current_user.add_notification('unread_message_count',0)
AttributeError: 'User' object has no attribute 'add_notification'
2023-04-11 19:46:47,043 INFO: Microblog startup [in /home/keai33/Flask___Mega/microblog/app/__init__.py:78]
